/media/horst/189c70b7-c3e2-4746-b330-e3da14ecbc9f/music/Groinoids/Radiobeat Sessions 7_/04 Doy Doy Doy.mp3
ValueError: 255 is not a valid PictureType

During handling of the above exception, another exception occurred:

Traceback (most recent call last):
  File "./main.py", line 17, in <module>
    raise error
  File "./main.py", line 11, in <module>
    print(tag, *(repr(frame) for frame in tag), sep="\n")
  File "./main.py", line 11, in <genexpr>
    print(tag, *(repr(frame) for frame in tag), sep="\n")
  File "/home/horst/projects/id3vx/src/id3vx/frame.py", line 167, in __repr__
    return f'{type(self).__name__}(' \
  File "/home/horst/projects/id3vx/src/id3vx/frame.py", line 243, in __str__
    return f"[mime-type={self.mime_type()}]" \
  File "/home/horst/projects/id3vx/src/id3vx/frame.py", line 231, in picture_type
    return self.PictureType(int(self._picture_type))
  File "/home/horst/virtualenvironments/id3vx-YvnPDhJw/lib/python3.7/enum.py", line 310, in __call__
    return cls.__new__(cls, value)
  File "/home/horst/virtualenvironments/id3vx-YvnPDhJw/lib/python3.7/enum.py", line 564, in __new__
    raise exc
  File "/home/horst/virtualenvironments/id3vx-YvnPDhJw/lib/python3.7/enum.py", line 548, in __new__
    result = cls._missing_(value)
  File "/home/horst/virtualenvironments/id3vx-YvnPDhJw/lib/python3.7/enum.py", line 577, in _missing_
    raise ValueError("%r is not a valid %s" % (value, cls.__name__))
ValueError: 255 is not a valid PictureType
/media/horst/189c70b7-c3e2-4746-b330-e3da14ecbc9f/music/Groinoids/Radiobeat Sessions 7_/03 Burn.mp3
ValueError: 255 is not a valid PictureType

During handling of the above exception, another exception occurred:

Traceback (most recent call last):
  File "./main.py", line 17, in <module>
    raise error
  File "./main.py", line 11, in <module>
    print(tag, *(repr(frame) for frame in tag), sep="\n")
  File "./main.py", line 11, in <genexpr>
    print(tag, *(repr(frame) for frame in tag), sep="\n")
  File "/home/horst/projects/id3vx/src/id3vx/frame.py", line 167, in __repr__
    return f'{type(self).__name__}(' \
  File "/home/horst/projects/id3vx/src/id3vx/frame.py", line 243, in __str__
    return f"[mime-type={self.mime_type()}]" \
  File "/home/horst/projects/id3vx/src/id3vx/frame.py", line 231, in picture_type
    return self.PictureType(int(self._picture_type))
  File "/home/horst/virtualenvironments/id3vx-YvnPDhJw/lib/python3.7/enum.py", line 310, in __call__
    return cls.__new__(cls, value)
  File "/home/horst/virtualenvironments/id3vx-YvnPDhJw/lib/python3.7/enum.py", line 564, in __new__
    raise exc
  File "/home/horst/virtualenvironments/id3vx-YvnPDhJw/lib/python3.7/enum.py", line 548, in __new__
    result = cls._missing_(value)
  File "/home/horst/virtualenvironments/id3vx-YvnPDhJw/lib/python3.7/enum.py", line 577, in _missing_
    raise ValueError("%r is not a valid %s" % (value, cls.__name__))
ValueError: 255 is not a valid PictureType
/media/horst/189c70b7-c3e2-4746-b330-e3da14ecbc9f/music/Groinoids/Radiobeat Sessions 7_/01 Angel.mp3
ValueError: 255 is not a valid PictureType

During handling of the above exception, another exception occurred:

Traceback (most recent call last):
  File "./main.py", line 17, in <module>
    raise error
  File "./main.py", line 11, in <module>
    print(tag, *(repr(frame) for frame in tag), sep="\n")
  File "./main.py", line 11, in <genexpr>
    print(tag, *(repr(frame) for frame in tag), sep="\n")
  File "/home/horst/projects/id3vx/src/id3vx/frame.py", line 167, in __repr__
    return f'{type(self).__name__}(' \
  File "/home/horst/projects/id3vx/src/id3vx/frame.py", line 243, in __str__
    return f"[mime-type={self.mime_type()}]" \
  File "/home/horst/projects/id3vx/src/id3vx/frame.py", line 231, in picture_type
    return self.PictureType(int(self._picture_type))
  File "/home/horst/virtualenvironments/id3vx-YvnPDhJw/lib/python3.7/enum.py", line 310, in __call__
    return cls.__new__(cls, value)
  File "/home/horst/virtualenvironments/id3vx-YvnPDhJw/lib/python3.7/enum.py", line 564, in __new__
    raise exc
  File "/home/horst/virtualenvironments/id3vx-YvnPDhJw/lib/python3.7/enum.py", line 548, in __new__
    result = cls._missing_(value)
  File "/home/horst/virtualenvironments/id3vx-YvnPDhJw/lib/python3.7/enum.py", line 577, in _missing_
    raise ValueError("%r is not a valid %s" % (value, cls.__name__))
ValueError: 255 is not a valid PictureType
/media/horst/189c70b7-c3e2-4746-b330-e3da14ecbc9f/music/Groinoids/Radiobeat Sessions 7_/02 Empty Skull.mp3
ValueError: 255 is not a valid PictureType

During handling of the above exception, another exception occurred:

Traceback (most recent call last):
  File "./main.py", line 17, in <module>
    raise error
  File "./main.py", line 11, in <module>
    print(tag, *(repr(frame) for frame in tag), sep="\n")
  File "./main.py", line 11, in <genexpr>
    print(tag, *(repr(frame) for frame in tag), sep="\n")
  File "/home/horst/projects/id3vx/src/id3vx/frame.py", line 167, in __repr__
    return f'{type(self).__name__}(' \
  File "/home/horst/projects/id3vx/src/id3vx/frame.py", line 243, in __str__
    return f"[mime-type={self.mime_type()}]" \
  File "/home/horst/projects/id3vx/src/id3vx/frame.py", line 231, in picture_type
    return self.PictureType(int(self._picture_type))
  File "/home/horst/virtualenvironments/id3vx-YvnPDhJw/lib/python3.7/enum.py", line 310, in __call__
    return cls.__new__(cls, value)
  File "/home/horst/virtualenvironments/id3vx-YvnPDhJw/lib/python3.7/enum.py", line 564, in __new__
    raise exc
  File "/home/horst/virtualenvironments/id3vx-YvnPDhJw/lib/python3.7/enum.py", line 548, in __new__
    result = cls._missing_(value)
  File "/home/horst/virtualenvironments/id3vx-YvnPDhJw/lib/python3.7/enum.py", line 577, in _missing_
    raise ValueError("%r is not a valid %s" % (value, cls.__name__))
ValueError: 255 is not a valid PictureType
/media/horst/189c70b7-c3e2-4746-b330-e3da14ecbc9f/music/Groinoids/Radiobeat Sessions 7_/05 4.6 Billion Vampires.mp3
ValueError: 255 is not a valid PictureType

During handling of the above exception, another exception occurred:

Traceback (most recent call last):
  File "./main.py", line 17, in <module>
    raise error
  File "./main.py", line 11, in <module>
    print(tag, *(repr(frame) for frame in tag), sep="\n")
  File "./main.py", line 11, in <genexpr>
    print(tag, *(repr(frame) for frame in tag), sep="\n")
  File "/home/horst/projects/id3vx/src/id3vx/frame.py", line 167, in __repr__
    return f'{type(self).__name__}(' \
  File "/home/horst/projects/id3vx/src/id3vx/frame.py", line 243, in __str__
    return f"[mime-type={self.mime_type()}]" \
  File "/home/horst/projects/id3vx/src/id3vx/frame.py", line 231, in picture_type
    return self.PictureType(int(self._picture_type))
  File "/home/horst/virtualenvironments/id3vx-YvnPDhJw/lib/python3.7/enum.py", line 310, in __call__
    return cls.__new__(cls, value)
  File "/home/horst/virtualenvironments/id3vx-YvnPDhJw/lib/python3.7/enum.py", line 564, in __new__
    raise exc
  File "/home/horst/virtualenvironments/id3vx-YvnPDhJw/lib/python3.7/enum.py", line 548, in __new__
    result = cls._missing_(value)
  File "/home/horst/virtualenvironments/id3vx-YvnPDhJw/lib/python3.7/enum.py", line 577, in _missing_
    raise ValueError("%r is not a valid %s" % (value, cls.__name__))
ValueError: 255 is not a valid PictureType
/media/horst/189c70b7-c3e2-4746-b330-e3da14ecbc9f/music/Social Distortion/White Light White Heat White Trash/05 Through These Eyes.mp3
ValueError: 137 is not a valid PictureType

During handling of the above exception, another exception occurred:

Traceback (most recent call last):
  File "./main.py", line 17, in <module>
    raise error
  File "./main.py", line 11, in <module>
    print(tag, *(repr(frame) for frame in tag), sep="\n")
  File "./main.py", line 11, in <genexpr>
    print(tag, *(repr(frame) for frame in tag), sep="\n")
  File "/home/horst/projects/id3vx/src/id3vx/frame.py", line 167, in __repr__
    return f'{type(self).__name__}(' \
  File "/home/horst/projects/id3vx/src/id3vx/frame.py", line 243, in __str__
    return f"[mime-type={self.mime_type()}]" \
  File "/home/horst/projects/id3vx/src/id3vx/frame.py", line 231, in picture_type
    return self.PictureType(int(self._picture_type))
  File "/home/horst/virtualenvironments/id3vx-YvnPDhJw/lib/python3.7/enum.py", line 310, in __call__
    return cls.__new__(cls, value)
  File "/home/horst/virtualenvironments/id3vx-YvnPDhJw/lib/python3.7/enum.py", line 564, in __new__
    raise exc
  File "/home/horst/virtualenvironments/id3vx-YvnPDhJw/lib/python3.7/enum.py", line 548, in __new__
    result = cls._missing_(value)
  File "/home/horst/virtualenvironments/id3vx-YvnPDhJw/lib/python3.7/enum.py", line 577, in _missing_
    raise ValueError("%r is not a valid %s" % (value, cls.__name__))
ValueError: 137 is not a valid PictureType
/media/horst/189c70b7-c3e2-4746-b330-e3da14ecbc9f/music/Social Distortion/White Light White Heat White Trash/02 Don't Drag Me Down.mp3
ValueError: 137 is not a valid PictureType

During handling of the above exception, another exception occurred:

Traceback (most recent call last):
  File "./main.py", line 17, in <module>
    raise error
  File "./main.py", line 11, in <module>
    print(tag, *(repr(frame) for frame in tag), sep="\n")
  File "./main.py", line 11, in <genexpr>
    print(tag, *(repr(frame) for frame in tag), sep="\n")
  File "/home/horst/projects/id3vx/src/id3vx/frame.py", line 167, in __repr__
    return f'{type(self).__name__}(' \
  File "/home/horst/projects/id3vx/src/id3vx/frame.py", line 243, in __str__
    return f"[mime-type={self.mime_type()}]" \
  File "/home/horst/projects/id3vx/src/id3vx/frame.py", line 231, in picture_type
    return self.PictureType(int(self._picture_type))
  File "/home/horst/virtualenvironments/id3vx-YvnPDhJw/lib/python3.7/enum.py", line 310, in __call__
    return cls.__new__(cls, value)
  File "/home/horst/virtualenvironments/id3vx-YvnPDhJw/lib/python3.7/enum.py", line 564, in __new__
    raise exc
  File "/home/horst/virtualenvironments/id3vx-YvnPDhJw/lib/python3.7/enum.py", line 548, in __new__
    result = cls._missing_(value)
  File "/home/horst/virtualenvironments/id3vx-YvnPDhJw/lib/python3.7/enum.py", line 577, in _missing_
    raise ValueError("%r is not a valid %s" % (value, cls.__name__))
ValueError: 137 is not a valid PictureType
/media/horst/189c70b7-c3e2-4746-b330-e3da14ecbc9f/music/Social Distortion/White Light White Heat White Trash/12 Under My Thumb.mp3
ValueError: 137 is not a valid PictureType

During handling of the above exception, another exception occurred:

Traceback (most recent call last):
  File "./main.py", line 17, in <module>
    raise error
  File "./main.py", line 11, in <module>
    print(tag, *(repr(frame) for frame in tag), sep="\n")
  File "./main.py", line 11, in <genexpr>
    print(tag, *(repr(frame) for frame in tag), sep="\n")
  File "/home/horst/projects/id3vx/src/id3vx/frame.py", line 167, in __repr__
    return f'{type(self).__name__}(' \
  File "/home/horst/projects/id3vx/src/id3vx/frame.py", line 243, in __str__
    return f"[mime-type={self.mime_type()}]" \
  File "/home/horst/projects/id3vx/src/id3vx/frame.py", line 231, in picture_type
    return self.PictureType(int(self._picture_type))
  File "/home/horst/virtualenvironments/id3vx-YvnPDhJw/lib/python3.7/enum.py", line 310, in __call__
    return cls.__new__(cls, value)
  File "/home/horst/virtualenvironments/id3vx-YvnPDhJw/lib/python3.7/enum.py", line 564, in __new__
    raise exc
  File "/home/horst/virtualenvironments/id3vx-YvnPDhJw/lib/python3.7/enum.py", line 548, in __new__
    result = cls._missing_(value)
  File "/home/horst/virtualenvironments/id3vx-YvnPDhJw/lib/python3.7/enum.py", line 577, in _missing_
    raise ValueError("%r is not a valid %s" % (value, cls.__name__))
ValueError: 137 is not a valid PictureType
/media/horst/189c70b7-c3e2-4746-b330-e3da14ecbc9f/music/Social Distortion/White Light White Heat White Trash/04 I Was Wrong.mp3
ValueError: 137 is not a valid PictureType

During handling of the above exception, another exception occurred:

Traceback (most recent call last):
  File "./main.py", line 17, in <module>
    raise error
  File "./main.py", line 11, in <module>
    print(tag, *(repr(frame) for frame in tag), sep="\n")
  File "./main.py", line 11, in <genexpr>
    print(tag, *(repr(frame) for frame in tag), sep="\n")
  File "/home/horst/projects/id3vx/src/id3vx/frame.py", line 167, in __repr__
    return f'{type(self).__name__}(' \
  File "/home/horst/projects/id3vx/src/id3vx/frame.py", line 243, in __str__
    return f"[mime-type={self.mime_type()}]" \
  File "/home/horst/projects/id3vx/src/id3vx/frame.py", line 231, in picture_type
    return self.PictureType(int(self._picture_type))
  File "/home/horst/virtualenvironments/id3vx-YvnPDhJw/lib/python3.7/enum.py", line 310, in __call__
    return cls.__new__(cls, value)
  File "/home/horst/virtualenvironments/id3vx-YvnPDhJw/lib/python3.7/enum.py", line 564, in __new__
    raise exc
  File "/home/horst/virtualenvironments/id3vx-YvnPDhJw/lib/python3.7/enum.py", line 548, in __new__
    result = cls._missing_(value)
  File "/home/horst/virtualenvironments/id3vx-YvnPDhJw/lib/python3.7/enum.py", line 577, in _missing_
    raise ValueError("%r is not a valid %s" % (value, cls.__name__))
ValueError: 137 is not a valid PictureType
/media/horst/189c70b7-c3e2-4746-b330-e3da14ecbc9f/music/Social Distortion/White Light White Heat White Trash/09 Crown Of Thorns.mp3
ValueError: 137 is not a valid PictureType

During handling of the above exception, another exception occurred:

Traceback (most recent call last):
  File "./main.py", line 17, in <module>
    raise error
  File "./main.py", line 11, in <module>
    print(tag, *(repr(frame) for frame in tag), sep="\n")
  File "./main.py", line 11, in <genexpr>
    print(tag, *(repr(frame) for frame in tag), sep="\n")
  File "/home/horst/projects/id3vx/src/id3vx/frame.py", line 167, in __repr__
    return f'{type(self).__name__}(' \
  File "/home/horst/projects/id3vx/src/id3vx/frame.py", line 243, in __str__
    return f"[mime-type={self.mime_type()}]" \
  File "/home/horst/projects/id3vx/src/id3vx/frame.py", line 231, in picture_type
    return self.PictureType(int(self._picture_type))
  File "/home/horst/virtualenvironments/id3vx-YvnPDhJw/lib/python3.7/enum.py", line 310, in __call__
    return cls.__new__(cls, value)
  File "/home/horst/virtualenvironments/id3vx-YvnPDhJw/lib/python3.7/enum.py", line 564, in __new__
    raise exc
  File "/home/horst/virtualenvironments/id3vx-YvnPDhJw/lib/python3.7/enum.py", line 548, in __new__
    result = cls._missing_(value)
  File "/home/horst/virtualenvironments/id3vx-YvnPDhJw/lib/python3.7/enum.py", line 577, in _missing_
    raise ValueError("%r is not a valid %s" % (value, cls.__name__))
ValueError: 137 is not a valid PictureType
/media/horst/189c70b7-c3e2-4746-b330-e3da14ecbc9f/music/Social Distortion/White Light White Heat White Trash/06 Down On The World.mp3
ValueError: 137 is not a valid PictureType

During handling of the above exception, another exception occurred:

Traceback (most recent call last):
  File "./main.py", line 17, in <module>
    raise error
  File "./main.py", line 11, in <module>
    print(tag, *(repr(frame) for frame in tag), sep="\n")
  File "./main.py", line 11, in <genexpr>
    print(tag, *(repr(frame) for frame in tag), sep="\n")
  File "/home/horst/projects/id3vx/src/id3vx/frame.py", line 167, in __repr__
    return f'{type(self).__name__}(' \
  File "/home/horst/projects/id3vx/src/id3vx/frame.py", line 243, in __str__
    return f"[mime-type={self.mime_type()}]" \
  File "/home/horst/projects/id3vx/src/id3vx/frame.py", line 231, in picture_type
    return self.PictureType(int(self._picture_type))
  File "/home/horst/virtualenvironments/id3vx-YvnPDhJw/lib/python3.7/enum.py", line 310, in __call__
    return cls.__new__(cls, value)
  File "/home/horst/virtualenvironments/id3vx-YvnPDhJw/lib/python3.7/enum.py", line 564, in __new__
    raise exc
  File "/home/horst/virtualenvironments/id3vx-YvnPDhJw/lib/python3.7/enum.py", line 548, in __new__
    result = cls._missing_(value)
  File "/home/horst/virtualenvironments/id3vx-YvnPDhJw/lib/python3.7/enum.py", line 577, in _missing_
    raise ValueError("%r is not a valid %s" % (value, cls.__name__))
ValueError: 137 is not a valid PictureType
/media/horst/189c70b7-c3e2-4746-b330-e3da14ecbc9f/music/Social Distortion/White Light White Heat White Trash/07 When Angels Sing.mp3
ValueError: 137 is not a valid PictureType

During handling of the above exception, another exception occurred:

Traceback (most recent call last):
  File "./main.py", line 17, in <module>
    raise error
  File "./main.py", line 11, in <module>
    print(tag, *(repr(frame) for frame in tag), sep="\n")
  File "./main.py", line 11, in <genexpr>
    print(tag, *(repr(frame) for frame in tag), sep="\n")
  File "/home/horst/projects/id3vx/src/id3vx/frame.py", line 167, in __repr__
    return f'{type(self).__name__}(' \
  File "/home/horst/projects/id3vx/src/id3vx/frame.py", line 243, in __str__
    return f"[mime-type={self.mime_type()}]" \
  File "/home/horst/projects/id3vx/src/id3vx/frame.py", line 231, in picture_type
    return self.PictureType(int(self._picture_type))
  File "/home/horst/virtualenvironments/id3vx-YvnPDhJw/lib/python3.7/enum.py", line 310, in __call__
    return cls.__new__(cls, value)
  File "/home/horst/virtualenvironments/id3vx-YvnPDhJw/lib/python3.7/enum.py", line 564, in __new__
    raise exc
  File "/home/horst/virtualenvironments/id3vx-YvnPDhJw/lib/python3.7/enum.py", line 548, in __new__
    result = cls._missing_(value)
  File "/home/horst/virtualenvironments/id3vx-YvnPDhJw/lib/python3.7/enum.py", line 577, in _missing_
    raise ValueError("%r is not a valid %s" % (value, cls.__name__))
ValueError: 137 is not a valid PictureType
/media/horst/189c70b7-c3e2-4746-b330-e3da14ecbc9f/music/Social Distortion/White Light White Heat White Trash/08 Gotta Know The Rules.mp3
ValueError: 137 is not a valid PictureType

During handling of the above exception, another exception occurred:

Traceback (most recent call last):
  File "./main.py", line 17, in <module>
    raise error
  File "./main.py", line 11, in <module>
    print(tag, *(repr(frame) for frame in tag), sep="\n")
  File "./main.py", line 11, in <genexpr>
    print(tag, *(repr(frame) for frame in tag), sep="\n")
  File "/home/horst/projects/id3vx/src/id3vx/frame.py", line 167, in __repr__
    return f'{type(self).__name__}(' \
  File "/home/horst/projects/id3vx/src/id3vx/frame.py", line 243, in __str__
    return f"[mime-type={self.mime_type()}]" \
  File "/home/horst/projects/id3vx/src/id3vx/frame.py", line 231, in picture_type
    return self.PictureType(int(self._picture_type))
  File "/home/horst/virtualenvironments/id3vx-YvnPDhJw/lib/python3.7/enum.py", line 310, in __call__
    return cls.__new__(cls, value)
  File "/home/horst/virtualenvironments/id3vx-YvnPDhJw/lib/python3.7/enum.py", line 564, in __new__
    raise exc
  File "/home/horst/virtualenvironments/id3vx-YvnPDhJw/lib/python3.7/enum.py", line 548, in __new__
    result = cls._missing_(value)
  File "/home/horst/virtualenvironments/id3vx-YvnPDhJw/lib/python3.7/enum.py", line 577, in _missing_
    raise ValueError("%r is not a valid %s" % (value, cls.__name__))
ValueError: 137 is not a valid PictureType
/media/horst/189c70b7-c3e2-4746-b330-e3da14ecbc9f/music/Social Distortion/White Light White Heat White Trash/01 Dear Lover.mp3
ValueError: 137 is not a valid PictureType

During handling of the above exception, another exception occurred:

Traceback (most recent call last):
  File "./main.py", line 17, in <module>
    raise error
  File "./main.py", line 11, in <module>
    print(tag, *(repr(frame) for frame in tag), sep="\n")
  File "./main.py", line 11, in <genexpr>
    print(tag, *(repr(frame) for frame in tag), sep="\n")
  File "/home/horst/projects/id3vx/src/id3vx/frame.py", line 167, in __repr__
    return f'{type(self).__name__}(' \
  File "/home/horst/projects/id3vx/src/id3vx/frame.py", line 243, in __str__
    return f"[mime-type={self.mime_type()}]" \
  File "/home/horst/projects/id3vx/src/id3vx/frame.py", line 231, in picture_type
    return self.PictureType(int(self._picture_type))
  File "/home/horst/virtualenvironments/id3vx-YvnPDhJw/lib/python3.7/enum.py", line 310, in __call__
    return cls.__new__(cls, value)
  File "/home/horst/virtualenvironments/id3vx-YvnPDhJw/lib/python3.7/enum.py", line 564, in __new__
    raise exc
  File "/home/horst/virtualenvironments/id3vx-YvnPDhJw/lib/python3.7/enum.py", line 548, in __new__
    result = cls._missing_(value)
  File "/home/horst/virtualenvironments/id3vx-YvnPDhJw/lib/python3.7/enum.py", line 577, in _missing_
    raise ValueError("%r is not a valid %s" % (value, cls.__name__))
ValueError: 137 is not a valid PictureType
/media/horst/189c70b7-c3e2-4746-b330-e3da14ecbc9f/music/Social Distortion/White Light White Heat White Trash/10 Pleasure Seeker.mp3
ValueError: 137 is not a valid PictureType

During handling of the above exception, another exception occurred:

Traceback (most recent call last):
  File "./main.py", line 17, in <module>
    raise error
  File "./main.py", line 11, in <module>
    print(tag, *(repr(frame) for frame in tag), sep="\n")
  File "./main.py", line 11, in <genexpr>
    print(tag, *(repr(frame) for frame in tag), sep="\n")
  File "/home/horst/projects/id3vx/src/id3vx/frame.py", line 167, in __repr__
    return f'{type(self).__name__}(' \
  File "/home/horst/projects/id3vx/src/id3vx/frame.py", line 243, in __str__
    return f"[mime-type={self.mime_type()}]" \
  File "/home/horst/projects/id3vx/src/id3vx/frame.py", line 231, in picture_type
    return self.PictureType(int(self._picture_type))
  File "/home/horst/virtualenvironments/id3vx-YvnPDhJw/lib/python3.7/enum.py", line 310, in __call__
    return cls.__new__(cls, value)
  File "/home/horst/virtualenvironments/id3vx-YvnPDhJw/lib/python3.7/enum.py", line 564, in __new__
    raise exc
  File "/home/horst/virtualenvironments/id3vx-YvnPDhJw/lib/python3.7/enum.py", line 548, in __new__
    result = cls._missing_(value)
  File "/home/horst/virtualenvironments/id3vx-YvnPDhJw/lib/python3.7/enum.py", line 577, in _missing_
    raise ValueError("%r is not a valid %s" % (value, cls.__name__))
ValueError: 137 is not a valid PictureType
/media/horst/189c70b7-c3e2-4746-b330-e3da14ecbc9f/music/Social Distortion/White Light White Heat White Trash/11 Down Here (With The Rest Of Us).mp3
ValueError: 137 is not a valid PictureType

During handling of the above exception, another exception occurred:

Traceback (most recent call last):
  File "./main.py", line 17, in <module>
    raise error
  File "./main.py", line 11, in <module>
    print(tag, *(repr(frame) for frame in tag), sep="\n")
  File "./main.py", line 11, in <genexpr>
    print(tag, *(repr(frame) for frame in tag), sep="\n")
  File "/home/horst/projects/id3vx/src/id3vx/frame.py", line 167, in __repr__
    return f'{type(self).__name__}(' \
  File "/home/horst/projects/id3vx/src/id3vx/frame.py", line 243, in __str__
    return f"[mime-type={self.mime_type()}]" \
  File "/home/horst/projects/id3vx/src/id3vx/frame.py", line 231, in picture_type
    return self.PictureType(int(self._picture_type))
  File "/home/horst/virtualenvironments/id3vx-YvnPDhJw/lib/python3.7/enum.py", line 310, in __call__
    return cls.__new__(cls, value)
  File "/home/horst/virtualenvironments/id3vx-YvnPDhJw/lib/python3.7/enum.py", line 564, in __new__
    raise exc
  File "/home/horst/virtualenvironments/id3vx-YvnPDhJw/lib/python3.7/enum.py", line 548, in __new__
    result = cls._missing_(value)
  File "/home/horst/virtualenvironments/id3vx-YvnPDhJw/lib/python3.7/enum.py", line 577, in _missing_
    raise ValueError("%r is not a valid %s" % (value, cls.__name__))
ValueError: 137 is not a valid PictureType
/media/horst/189c70b7-c3e2-4746-b330-e3da14ecbc9f/music/Social Distortion/White Light White Heat White Trash/03 Untitled.mp3
ValueError: 137 is not a valid PictureType

During handling of the above exception, another exception occurred:

Traceback (most recent call last):
  File "./main.py", line 17, in <module>
    raise error
  File "./main.py", line 11, in <module>
    print(tag, *(repr(frame) for frame in tag), sep="\n")
  File "./main.py", line 11, in <genexpr>
    print(tag, *(repr(frame) for frame in tag), sep="\n")
  File "/home/horst/projects/id3vx/src/id3vx/frame.py", line 167, in __repr__
    return f'{type(self).__name__}(' \
  File "/home/horst/projects/id3vx/src/id3vx/frame.py", line 243, in __str__
    return f"[mime-type={self.mime_type()}]" \
  File "/home/horst/projects/id3vx/src/id3vx/frame.py", line 231, in picture_type
    return self.PictureType(int(self._picture_type))
  File "/home/horst/virtualenvironments/id3vx-YvnPDhJw/lib/python3.7/enum.py", line 310, in __call__
    return cls.__new__(cls, value)
  File "/home/horst/virtualenvironments/id3vx-YvnPDhJw/lib/python3.7/enum.py", line 564, in __new__
    raise exc
  File "/home/horst/virtualenvironments/id3vx-YvnPDhJw/lib/python3.7/enum.py", line 548, in __new__
    result = cls._missing_(value)
  File "/home/horst/virtualenvironments/id3vx-YvnPDhJw/lib/python3.7/enum.py", line 577, in _missing_
    raise ValueError("%r is not a valid %s" % (value, cls.__name__))
ValueError: 137 is not a valid PictureType
